<?xml version="1.0" ?>
<!-- =================================================================================== -->
<!-- |    This document was autogenerated by xacro from darwin.urdf.xacro              | -->
<!-- |    EDITING THIS FILE BY HAND IS NOT RECOMMENDED                                 | -->
<!-- =================================================================================== -->
<robot name="darwin">
  <material name="black">
    <color rgba="0.0 0.0 0.0 1.0"/>
  </material>
  <material name="blue">
    <color rgba="0.0 0.0 0.8 1.0"/>
  </material>
  <material name="green">
    <color rgba="0.0 0.8 0.0 1.0"/>
  </material>
  <material name="grey">
    <color rgba="0.60 0.60 0.60 1.0"/>
  </material>
  <material name="orange">
    <color rgba="1.0 0.4235294117647059 0.0392156862745098 1.0"/>
  </material>
  <material name="brown">
    <color rgba="0.8705882352941177 0.8117647058823529 0.7647058823529411 1.0"/>
  </material>
  <material name="red">
    <color rgba="0.8 0.0 0.0 1.0"/>
  </material>
  <material name="white">
    <color rgba="1.0 1.0 1.0 1.0"/>
  </material>
  <material name="beige">
    <color rgba="0.98 0.915 0.72 1.0"/>
  </material>
  <material name="temp">
    <color rgba="0.5 0.5 0.8 1.0"/>
  </material>
  <link name="base_link">
    <inertial>
    <origin xyz="0 0 0" rpy="0 0 0" />
    <mass value="1e-9" />
    <inertia ixx="0" ixy="0" ixz="0" iyy="0" iyz="0" izz="0" />
    </inertial>
    </link>
  <link name="imu_frame">
    <inertial>
    <origin xyz="0 0 0" rpy="0 0 0" />
    <mass value="1e-9" />
    <inertia ixx="0" ixy="0" ixz="0" iyy="0" iyz="0" izz="0" />
    </inertial>
    </link>
  <link name="MP_BODY">
    <inertial>
      <origin xyz="-0.003053 -0.038651 -0.019268"/>
      <mass value="0.97559947"/>
      <inertia ixx="3.1081800" ixy="-0.25460189" ixz="2.0318174" iyy="6.3787776" iyz="0.16417863" izz="5.3316425"/>
    </inertial>
    <collision>
      <origin rpy="0 0 0" xyz="-0.0235 0 -0.03525"/>
      <geometry>
        <box size="0.102 0.109 0.106"/>
      </geometry>
    </collision>
    <visual>
      <origin rpy="0 0 0" xyz="0 0 0"/>
      <geometry>
        <mesh filename="package://darwin_description/meshes/body.STL" scale="1 1 1"/>
      </geometry>
      <material name="grey"/>
    </visual>
  </link>
  <joint name="base_link_to_body" type="fixed">
    <parent link="base_link"/>
    <child link="MP_BODY"/>
    <origin rpy="0 0 0" xyz="0.005 0 0.09355"/>
  </joint>
  <joint name="base_link_to_imu" type="fixed">
    <parent link="base_link"/>
    <child link="imu_frame"/>
    <origin rpy="0 0 0" xyz="0 0 0"/>
  </joint>
  <gazebo>
    <plugin filename="libhector_gazebo_ros_imu.so" name="gazebo_ros_imu">
      <bodyName>MP_BODY</bodyName>
      <updateRate>50</updateRate>
      <serviceName>/darwin/imu_service</serviceName>
      <topicName>/darwin/imu</topicName>
      <gaussianNoise>0</gaussianNoise>
      <xyzOffset>0 0 0</xyzOffset>
      <rpyOffset>0 0 -0.703220730592</rpyOffset>
    </plugin>
  </gazebo>
  <link name="MP_BACK_L">
    <inertial>
      <origin xyz="-0.0031158909 0.020443695 -0.019663084"/>
      <mass value="0.010"/>
      <inertia ixx="3.1081800" ixy="-0.25460189" ixz="2.0318174" iyy="6.3787776" iyz="0.16417863" izz="5.3316425"/>
    </inertial>
    <collision>
      <origin xyz="-0.0031158909 0.020443695 -0.019663084"/>
      <geometry>
        <box scale="1 1 1" size="0.001 0.001 0.001"/>
      </geometry>
    </collision>
    <visual>
      <origin rpy="0 0 0" xyz="0.0 0.0 0.0"/>
      <geometry>
        <box scale="1 1 1" size="0.001 0.001 0.001"/>
      </geometry>
      <material name="grey"/>
    </visual>
  </link>
  <link name="MP_SHOULDER_L">
    <inertial>
      <origin xyz="-0.013522619 0.010264050 0.0013935747"/>
      <mass value="0.025913024"/>
      <inertia ixx="0.0097758165" ixy="0.0016911839" ixz="-0.00045174329" iyx="0.0016911839" iyy="0.010511104" iyz="0.00033406955" izx="-0.00045174329" izy="0.00033406955" izz="0.005476798"/>
    </inertial>
    <collision>
      <origin xyz="-0.013522619 -0.010264050 0.0013935747"/>
      <geometry>
        <box size="0.016 0.033 0.02165"/>
      </geometry>
    </collision>
    <visual>
      <origin rpy="0 0 0" xyz="0 0 0"/>
      <geometry>
        <mesh filename="package://darwin_description/meshes/shoulder_l.STL" scale="1 1 1"/>
      </geometry>
      <material name="grey"/>
    </visual>
  </link>
  <link name="MP_ARM_HIGH_L">
    <inertial>
      <origin xyz="-0.036239 0.000734 0.000660"/>
      <mass value="0.16837715"/>
      <inertia ixx="0.12202839" ixy="-0.0020812626" ixz="-0.00088143449" iyx="-0.0020812626" iyy="0.038088441" iyz="0.0018251448" izx="-0.00088143449" izy="0.0018251448" izz="0.11340830"/>
    </inertial>
    <collision>
      <origin xyz="-0.036239 0.000734 0.000660"/>
      <geometry>
        <box size="0.06 0.032 0.035"/>
      </geometry>
    </collision>
    <visual>
      <origin rpy="0 0 0" xyz="0 0 0"/>
      <geometry>
        <mesh filename="package://darwin_description/meshes/arm_high_l.STL" scale="1 1 1"/>
      </geometry>
      <material name="grey"/>
    </visual>
  </link>
  <link name="MP_ARM_LOW_L">
    <inertial>
      <origin xyz="0.000000 0.000000 0.000000"/>
      <mass value="0.059288504"/>
      <inertia ixx="0.086855267" ixy="0.0053020311" ixz="0.00043636051" iyx="0.0053020311" iyy="0.021192085" iyz="-0.0064855932" izx="0.00043636051" izy="-0.0064855932" izz="0.086845450"/>
    </inertial>
    <collision>
      <origin rpy="0 0 0" xyz="0.016 0.016 0"/>
      <geometry>
        <box size="0.032 0.032 0.035"/>
      </geometry>
    </collision>
    <visual>
      <origin rpy="0 0 0" xyz="0.016 0.016 0"/>
      <geometry>
        <box size="0.032 0.032 0.035"/>
      </geometry>
      <material name="grey"/>
    </visual>
  </link>
  <link name="MP_ARM_GRIPPER_FIX_L">
    <inertial>
      <origin xyz="0.045838 -0.013490 0.006666"/>
      <mass value="0.010"/>
      <inertia ixx="0.12202839" ixy="-0.0020812626" ixz="-0.00088143449" iyx="-0.0020812626" iyy="0.038088441" iyz="0.0018251448" izx="-0.00088143449" izy="0.0018251448" izz="0.11340830"/>
    </inertial>
    <collision>
      <origin rpy="0 0 0" xyz="0.016 0 0"/>
      <geometry>
        <box size="0.064 0.032 0.032"/>
      </geometry>
    </collision>
    <visual>
      <origin rpy="0 0 0" xyz="0.016 0 0"/>
      <geometry>
        <box size="0.064 0.032 0.032"/>
      </geometry>
      <material name="grey"/>
    </visual>
  </link>
  <link name="MP_ARM_GRIPPER_FIX_DUMMY_L">
    <inertial>
      <origin xyz="0 0 0"/>
      <mass value="0.010"/>
      <inertia ixx="0.12202839" ixy="-0.0020812626" ixz="-0.00088143449" iyx="-0.0020812626" iyy="0.038088441" iyz="0.0018251448" izx="-0.00088143449" izy="0.0018251448" izz="0.11340830"/>
    </inertial>
    <collision>
      <geometry>
        <box size="0.032 0.005 0.032"/>
      </geometry>
    </collision>
    <visual>
      <origin rpy="0 0 0" xyz="0 0 0"/>
      <geometry>
        <box size="0.032 0.005 0.032"/>
      </geometry>
      <material name="grey"/>
    </visual>
  </link>
  <link name="MP_ARM_GRIPPER_MOV_L">
    <inertial>
      <origin xyz="0.000000 0.000000 0.000000"/>
      <mass value="0.010"/>
      <inertia ixx="0.12202839" ixy="-0.0020812626" ixz="-0.00088143449" iyx="-0.0020812626" iyy="0.038088441" iyz="0.0018251448" izx="-0.00088143449" izy="0.0018251448" izz="0.11340830"/>
    </inertial>
    <collision name="COL_MP_ARM_GRIPPER_MOV_L">
      <origin rpy="0 0 0" xyz="0.016 0 0"/>
      <geometry>
        <box size="0.032 0.005 0.032"/>
      </geometry>
    </collision>
    <collision name="COL_MP_ARM_GRIPPER_MOV_EXT_L">
      <origin rpy="0 0 0" xyz="0.031 -0.0025 0"/>
      <geometry>
        <box size="0.002 0.01 0.032"/>
      </geometry>
    </collision>
    <visual name="VIS_MP_ARM_GRIPPER_MOV_L">
      <origin rpy="0 0 0" xyz="0.016 0 0"/>
      <geometry>
        <box size="0.032 0.005 0.032"/>
      </geometry>
      <material name="grey"/>
    </visual>
    <visual name="VIS_MP_ARM_GRIPPER_MOV_EXT_L">
      <origin rpy="0 0 0" xyz="0.031 -0.0025 0"/>
      <geometry>
        <box size="0.002 0.01 0.032"/>
      </geometry>
      <material name="grey"/>
    </visual>
  </link>
  <link name="MP_BACK_R">
    <inertial>
      <origin xyz="0 0 0"/>
      <mass value="0.010"/>
      <inertia ixx="3.1081800" ixy="-0.25460189" ixz="2.0318174" iyy="6.3787776" iyz="0.16417863" izz="5.3316425"/>
    </inertial>
    <collision>
      <geometry>
        <box size="0.001 0.001 0.001"/>
      </geometry>
    </collision>
    <visual>
      <origin rpy="0 0 0" xyz="0.0 0.0 0.0"/>
      <geometry>
        <box size="0.001 0.001 0.001"/>
      </geometry>
      <material name="grey"/>
    </visual>
  </link>
  <link name="MP_SHOULDER_R">
    <inertial>
      <origin xyz="-0.013523 0.010264 0.001394"/>
      <mass value="0.025913024"/>
      <inertia ixx="0.0097758165" ixy="0.0016911839" ixz="-0.00045174329" iyx="0.0016911839" iyy="0.010511104" iyz="0.00033406955" izx="-0.00045174329" izy="0.00033406955" izz="0.005476798"/>
    </inertial>
    <collision>
      <origin xyz="-0.013523 0.010264 0.001394"/>
      <geometry>
        <box size="0.016 0.033 0.02165"/>
      </geometry>
    </collision>
    <visual>
      <origin rpy="0 0 0" xyz="0 0 0"/>
      <geometry>
        <mesh filename="package://darwin_description/meshes/shoulder_r.STL" scale="1 1 1"/>
      </geometry>
      <material name="grey"/>
    </visual>
  </link>
  <link name="MP_ARM_HIGH_R">
    <inertial>
      <origin xyz="-0.036239 0.000734 -0.000660"/>
      <mass value="0.16837715"/>
      <inertia ixx="0.12202839" ixy="-0.0020812626" ixz="-0.00088143449" iyx="-0.0020812626" iyy="0.038088441" iyz="0.0018251448" izx="-0.00088143449" izy="0.0018251448" izz="0.11340830"/>
    </inertial>
    <collision>
      <origin xyz="-0.036239 0.000734 -0.000660"/>
      <geometry>
        <box size="0.06 0.032 0.035"/>
      </geometry>
    </collision>
    <visual>
      <origin rpy="0 0 0" xyz="0 0 0"/>
      <geometry>
        <mesh filename="package://darwin_description/meshes/arm_high_r.STL" scale="1 1 1"/>
      </geometry>
      <material name="grey"/>
    </visual>
  </link>
  <link name="MP_ARM_LOW_R">
    <inertial>
      <origin xyz="0.000000 0.000000 0.000000"/>
      <mass value="0.059288504"/>
      <inertia ixx="0.086855267" ixy="0.0053020311" ixz="0.00043636051" iyx="0.0053020311" iyy="0.021192085" iyz="-0.0064855932" izx="0.00043636051" izy="-0.0064855932" izz="0.086845450"/>
    </inertial>
    <collision>
      <origin rpy="0 0 0" xyz="0.016 -0.016 0"/>
      <geometry>
        <box size="0.032 0.032 0.035"/>
      </geometry>
    </collision>
    <visual>
      <origin rpy="0 0 0" xyz="0.016 -0.016 0"/>
      <geometry>
        <box size="0.032 0.032 0.035"/>
      </geometry>
      <material name="grey"/>
    </visual>
  </link>
  <link name="MP_ARM_GRIPPER_FIX_R">
    <inertial>
      <origin xyz="0 0 0"/>
      <mass value="0.010"/>
      <inertia ixx="0.12202839" ixy="-0.0020812626" ixz="-0.00088143449" iyx="-0.0020812626" iyy="0.038088441" iyz="0.0018251448" izx="-0.00088143449" izy="0.0018251448" izz="0.11340830"/>
    </inertial>
    <collision>
      <origin rpy="0 0 0" xyz="0.016 0 0"/>
      <geometry>
        <box size="0.064 0.032 0.032"/>
      </geometry>
    </collision>
    <visual>
      <origin rpy="0 0 0" xyz="0.016 0 0"/>
      <geometry>
        <box size="0.064 0.032 0.032"/>
      </geometry>
      <material name="grey"/>
    </visual>
  </link>
  <link name="MP_ARM_GRIPPER_FIX_DUMMY_R">
    <inertial>
      <origin xyz="0 0 0"/>
      <mass value="0.010"/>
      <inertia ixx="0.12202839" ixy="-0.0020812626" ixz="-0.00088143449" iyx="-0.0020812626" iyy="0.038088441" iyz="0.0018251448" izx="-0.00088143449" izy="0.0018251448" izz="0.11340830"/>
    </inertial>
    <collision>
      <geometry>
        <box size="0.032 0.005 0.032"/>
      </geometry>
    </collision>
    <visual>
      <origin rpy="0 0 0" xyz="0 0 0"/>
      <geometry>
        <box size="0.032 0.005 0.032"/>
      </geometry>
      <material name="grey"/>
    </visual>
  </link>
  <link name="MP_ARM_GRIPPER_MOV_R">
    <inertial>
      <origin xyz="0.000000 0.000000 0.000000"/>
      <mass value="0.010"/>
      <inertia ixx="0.12202839" ixy="-0.0020812626" ixz="-0.00088143449" iyx="-0.0020812626" iyy="0.038088441" iyz="0.0018251448" izx="-0.00088143449" izy="0.0018251448" izz="0.11340830"/>
    </inertial>
    <collision name="COL_MP_ARM_GRIPPER_MOV_R">
      <origin rpy="0 0 0" xyz="0.016 0 0"/>
      <geometry>
        <box size="0.032 0.005 0.032"/>
      </geometry>
    </collision>
    <collision name="COL_MP_ARM_GRIPPER_MOV_EXT_R">
      <origin rpy="0 0 0" xyz="0.031 -0.0025 0"/>
      <geometry>
        <box size="0.002 0.01 0.032"/>
      </geometry>
    </collision>
    <visual name="VIS_MP_ARM_GRIPPER_MOV_R">
      <origin rpy="0 0 0" xyz="0.016 0 0"/>
      <geometry>
        <box size="0.032 0.005 0.032"/>
      </geometry>
      <material name="grey"/>
    </visual>
    <visual name="VIS_MP_ARM_GRIPPER_MOV_EXT_R">
      <origin rpy="0 0 0" xyz="0.031 -0.0025 0"/>
      <geometry>
        <box size="0.002 0.01 0.032"/>
      </geometry>
      <material name="grey"/>
    </visual>
  </link>
  <joint name="j_back_l" type="fixed">
    <parent link="MP_BODY"/>
    <child link="MP_BACK_L"/>
    <origin rpy="-1.5707963 0 0" xyz="0 0.06035 0"/>
    <limit effort="2.8" lower="-2.6179939" upper="2.6179939" velocity="5.6548668"/>
  </joint>
  <joint name="LShoulderPitch" type="revolute">
    <parent link="MP_BACK_L"/>
    <child link="MP_SHOULDER_L"/>
    <origin rpy="0 0 -1.5707963" xyz="0 0 0"/>
    <axis xyz="0 0 1"/>
    <limit effort="2.8" lower="-3.14" upper="2.85" velocity="5.6548668"/>
  </joint>
  <joint name="LShoulderRoll" type="revolute">
    <parent link="MP_SHOULDER_L"/>
    <child link="MP_ARM_HIGH_L"/>
    <origin rpy="1.5707963 0.78539815 0" xyz="-0.016 0 0.02165"/>
    <axis xyz="0 0 1"/>
    <limit effort="2.8" lower="-2.25" upper="0.77" velocity="5.648668"/>
  </joint>
  <joint name="LElbow" type="revolute">
    <parent link="MP_ARM_HIGH_L"/>
    <child link="MP_ARM_LOW_L"/>
    <origin rpy="-1.5707963 1.5707963 0" xyz="-0.06 0 -0.016"/>
    <axis xyz="0 0 1"/>
    <limit effort="2.8" lower="-1.18" upper="1.63" velocity="5.6548668"/>
  </joint>
  <joint name="j_wrist_l" type="fixed">
    <parent link="MP_ARM_LOW_L"/>
    <child link="MP_ARM_GRIPPER_FIX_L"/>
    <origin rpy="1.5707963 0 0" xyz="0.048 0.016 0"/>
    <axis xyz="0 0 1"/>
    <limit effort="2.8" lower="-2.6179939" upper="2.6179939" velocity="5.6548668"/>
  </joint>
  <joint name="j_wrist_dummy_l" type="fixed">
    <parent link="MP_ARM_GRIPPER_FIX_L"/>
    <child link="MP_ARM_GRIPPER_FIX_DUMMY_L"/>
    <origin rpy="0 0 0" xyz="0.064 -0.01 0"/>
  </joint>
  <joint name="j_gripper_l" type="fixed">
    <parent link="MP_ARM_GRIPPER_FIX_L"/>
    <child link="MP_ARM_GRIPPER_MOV_L"/>
    <origin rpy="0 0 0" xyz="0.048 0.01 0"/>
    <axis xyz="0 0 1"/>
    <limit effort="2.8" lower="-2.6179939" upper="2.6179939" velocity="5.6548668"/>
  </joint>
  <joint name="j_back_r" type="fixed">
    <parent link="MP_BODY"/>
    <child link="MP_BACK_R"/>
    <origin rpy="1.5707963 0 0" xyz="0 -0.06035 0"/>
    <limit effort="2.8" lower="-2.6179939" upper="2.6179939" velocity="5.6548668"/>
  </joint>
  <joint name="RShoulderPitch" type="revolute">
    <parent link="MP_BACK_R"/>
    <child link="MP_SHOULDER_R"/>
    <origin rpy="0 0 1.5707963" xyz="0 0 0"/>
    <axis xyz="0 0 1"/>
    <limit effort="2.8" lower="-3.14" upper="3.14" velocity="5.6548668"/>
  </joint>
  <joint name="RShoulderRoll" type="revolute">
    <parent link="MP_SHOULDER_R"/>
    <child link="MP_ARM_HIGH_R"/>
    <origin rpy="-1.5707963 0.78539815 0" xyz="-0.016 0 0.02165"/>
    <axis xyz="0 0 1"/>
    <limit effort="2.8" lower="-0.68" upper="2.3" velocity="5.648668"/>
  </joint>
  <joint name="RElbow" type="revolute">
    <parent link="MP_ARM_HIGH_R"/>
    <child link="MP_ARM_LOW_R"/>
    <origin rpy="1.5707963 1.5707963 0" xyz="-0.06 0 -0.016"/>
    <axis xyz="0 0 1"/>
    <limit effort="2.8" lower="-1.65" upper="1.16" velocity="5.6548668"/>
  </joint>
  <joint name="j_wrist_r" type="fixed">
    <parent link="MP_ARM_LOW_R"/>
    <child link="MP_ARM_GRIPPER_FIX_R"/>
    <origin rpy="1.5707963 0 0" xyz="0.048 -0.016 0"/>
    <axis xyz="0 0 1"/>
    <limit effort="2.8" lower="-2.6179939" upper="2.6179939" velocity="5.6548668"/>
  </joint>
  <joint name="j_wrist_dummy_r" type="fixed">
    <parent link="MP_ARM_GRIPPER_FIX_R"/>
    <child link="MP_ARM_GRIPPER_FIX_DUMMY_R"/>
    <origin rpy="0 0 0" xyz="0.064 -0.01 0"/>
  </joint>
  <joint name="j_gripper_r" type="fixed">
    <parent link="MP_ARM_GRIPPER_FIX_R"/>
    <child link="MP_ARM_GRIPPER_MOV_R"/>
    <origin rpy="0 0 0" xyz="0.048 0.01 0"/>
    <axis xyz="0 0 1"/>
    <limit effort="2.8" lower="-2.6179939" upper="2.6179939" velocity="5.6548668"/>
  </joint>
  <transmission name="LShoulderRoll_transmssion">
    <type>transmission_interface/SimpleTransmission</type>
    <joint name="LShoulderRoll">
      <hardwareInterface>EffortJointInterface</hardwareInterface>
    </joint>
    <actuator name="LShoulderRoll_motor">
      <hardwareInterface>EffortJointInterface</hardwareInterface>
      <mechanicalReduction>1</mechanicalReduction>
    </actuator>
  </transmission>
  <gazebo reference="LShoulderRoll">
    <implicitSpringDamper>1</implicitSpringDamper>
  </gazebo>
  <transmission name="LShoulderPitch_transmssion">
    <type>transmission_interface/SimpleTransmission</type>
    <joint name="LShoulderPitch">
      <hardwareInterface>EffortJointInterface</hardwareInterface>
    </joint>
    <actuator name="LShoulderPitch_motor">
      <hardwareInterface>EffortJointInterface</hardwareInterface>
      <mechanicalReduction>1</mechanicalReduction>
    </actuator>
  </transmission>
  <gazebo reference="LShoulderPitch">
    <implicitSpringDamper>1</implicitSpringDamper>
  </gazebo>
  <transmission name="LElbow_transmssion">
    <type>transmission_interface/SimpleTransmission</type>
    <joint name="LElbow">
      <hardwareInterface>EffortJointInterface</hardwareInterface>
    </joint>
    <actuator name="LElbow_motor">
      <hardwareInterface>EffortJointInterface</hardwareInterface>
      <mechanicalReduction>1</mechanicalReduction>
    </actuator>
  </transmission>
  <gazebo reference="LElbow">
    <implicitSpringDamper>1</implicitSpringDamper>
  </gazebo>
  <transmission name="RShoulderRoll_transmssion">
    <type>transmission_interface/SimpleTransmission</type>
    <joint name="RShoulderRoll">
      <hardwareInterface>EffortJointInterface</hardwareInterface>
    </joint>
    <actuator name="RShoulderRoll_motor">
      <hardwareInterface>EffortJointInterface</hardwareInterface>
      <mechanicalReduction>1</mechanicalReduction>
    </actuator>
  </transmission>
  <gazebo reference="RShoulderRoll">
    <implicitSpringDamper>1</implicitSpringDamper>
  </gazebo>
  <transmission name="RShoulderPitch_transmssion">
    <type>transmission_interface/SimpleTransmission</type>
    <joint name="RShoulderPitch">
      <hardwareInterface>EffortJointInterface</hardwareInterface>
    </joint>
    <actuator name="RShoulderPitch_motor">
      <hardwareInterface>EffortJointInterface</hardwareInterface>
      <mechanicalReduction>1</mechanicalReduction>
    </actuator>
  </transmission>
  <gazebo reference="RShoulderPitch">
    <implicitSpringDamper>1</implicitSpringDamper>
  </gazebo>
  <transmission name="RElbow_transmssion">
    <type>transmission_interface/SimpleTransmission</type>
    <joint name="RElbow">
      <hardwareInterface>EffortJointInterface</hardwareInterface>
    </joint>
    <actuator name="RElbow_motor">
      <hardwareInterface>EffortJointInterface</hardwareInterface>
      <mechanicalReduction>1</mechanicalReduction>
    </actuator>
  </transmission>
  <gazebo reference="RElbow">
    <implicitSpringDamper>1</implicitSpringDamper>
  </gazebo>
  <link name="MP_NECK">
    <inertial>
      <origin xyz="0.001424 -0.016567 -0.007128"/>
      <mass value="0.024357719"/>
      <inertia ixx="0.0051411124" ixy="-0.00057530255" ixz="-0.000024729049" iyy="0.0081915737" iyz="-0.000019223094" izz="0.0011379812"/>
    </inertial>
    <collision>
      <origin xyz="0.0 -0.0 0.01525"/>
      <geometry>
        <box size="0.045 0.022 0.0325"/>
      </geometry>
    </collision>
    <visual>
      <origin rpy="0 0 0" xyz="0 0 0"/>
      <geometry>
        <mesh filename="package://darwin_description/meshes/neck.STL" scale="1 1 1"/>
      </geometry>
      <material name="grey"/>
    </visual>
  </link>
  <link name="MP_HEAD">
    <inertial>
      <origin xyz="0.000064 -0.018565 -0.007667"/>
      <mass value="0.15804192"/>
      <inertia ixx="0.1239683" ixy="0.000078494368" ixz="0.000007645979" iyy="0.11783781" iyz="0.0012199205" izz="0.1583601"/>
    </inertial>
    <collision>
      <origin xyz="0.000064 -0.018565 -0.0"/>
      <geometry>
        <sphere radius="0.044"/>
      </geometry>
    </collision>
    <visual>
      <origin rpy="0 0 0" xyz="0 0 0"/>
      <geometry>
        <mesh filename="package://darwin_description/meshes/head.STL" scale="1 1 1"/>
      </geometry>
      <material name="grey"/>
    </visual>
  </link>
  <link name="MP_PMDCAMBOARD">
  </link>
  <joint name="j_camboard" type="fixed">
    <parent link="MP_HEAD"/>
    <child link="MP_PMDCAMBOARD"/>
    <origin rpy="3.14159 1.5707963 0" xyz="0 0 0.0235"/>
    <axis xyz="0 0 1"/>
    <limit effort="2.8" lower="-2.6179939" upper="2.6179939" velocity="5.6548668"/>
  </joint>
  <joint name="HeadPan" type="revolute">
    <parent link="MP_BODY"/>
    <child link="MP_NECK"/>
    <origin rpy="0 0 1.5707963" xyz="0 0 0.0235"/>
    <axis xyz="0 0 1"/>
    <limit effort="2.8" lower="-1.81" upper="1.81" velocity="5.6548668"/>
  </joint>
  <joint name="HeadTilt" type="revolute">
    <parent link="MP_NECK"/>
    <child link="MP_HEAD"/>
    <origin rpy="-1.5707963 0 1.5707963" xyz="0 0 0.02715"/>
    <axis xyz="0 0 1"/>
    <limit effort="2.8" lower="-0.36" upper="0.94" velocity="5.6548668"/>
  </joint>
  <transmission name="HeadPan_transmssion">
    <type>transmission_interface/SimpleTransmission</type>
    <joint name="HeadPan">
      <hardwareInterface>EffortJointInterface</hardwareInterface>
    </joint>
    <actuator name="HeadPan_motor">
      <hardwareInterface>EffortJointInterface</hardwareInterface>
      <mechanicalReduction>1</mechanicalReduction>
    </actuator>
  </transmission>
  <gazebo reference="HeadPan">
    <implicitSpringDamper>1</implicitSpringDamper>
  </gazebo>
  <transmission name="HeadTilt_transmssion">
    <type>transmission_interface/SimpleTransmission</type>
    <joint name="HeadTilt">
      <hardwareInterface>EffortJointInterface</hardwareInterface>
    </joint>
    <actuator name="HeadTilt_motor">
      <hardwareInterface>EffortJointInterface</hardwareInterface>
      <mechanicalReduction>1</mechanicalReduction>
    </actuator>
  </transmission>
  <gazebo reference="HeadTilt">
    <implicitSpringDamper>1</implicitSpringDamper>
  </gazebo>
  <gazebo reference="MP_HEAD">
    <sensor name="camera" type="camera">
      <pose>-0.050000 -0.010000 0.000000 -1.5708 0.000000 -3.141592</pose>
      <camera name="__default__">
        <horizontal_fov>1.012300</horizontal_fov>
        <image>
          <width>320</width>
          <height>200</height>
        </image>
        <clip>
          <near>0.001000</near>
          <far>100.000000</far>
        </clip>
      </camera>
      <always_on>1</always_on>
      <update_rate>30.000000</update_rate>
      <visualize>1</visualize>
      <plugin filename="libgazebo_ros_camera.so" name="camera_controller">
        <alwaysOn>true</alwaysOn>
        <updateRate>30</updateRate>
        <cameraName>darwin/camera</cameraName>
        <imageTopicName>image_raw</imageTopicName>
        <cameraInfoTopicName>camera_info</cameraInfoTopicName>
        <frameName>camera_link</frameName>
        <hackBaseline>0.07</hackBaseline>
        <distortionK1>0.0</distortionK1>
        <distortionK2>0.0</distortionK2>
        <distortionK3>0.0</distortionK3>
        <distortionT1>0.0</distortionT1>
        <distortionT2>0.0</distortionT2>
      </plugin>
    </sensor>
  </gazebo>
  <link name="MP_PELVIS_L">
    <inertial>
      <origin xyz="0.000000 0.000480 0.018437"/>
      <mass value="0.167"/>
      <inertia ixx="0.12259691" ixy="0.00071127469" ixz="0.00081143913" iyx="0.00071127469" iyy="0.11066637" iyz="-0.0071635476" izx="0.00081143913" izy="-0.0071635476" izz="0.041877668"/>
    </inertial>
    <collision>
      <origin xyz="0.000000 -0.010580 0.028437"/>
      <geometry>
        <box size="0.045 0.08175 0.028652"/>
      </geometry>
    </collision>
    <visual>
      <origin rpy="0 0 0" xyz="0 0 0"/>
      <geometry>
        <mesh filename="package://darwin_description/meshes/pelvis_l.STL" scale="1 1 1"/>
      </geometry>
      <material name="grey"/>
    </visual>
  </link>
  <link name="MP_THIGH1_L">
    <inertial>
      <origin xyz="0.000079 0.018242 0.013873"/>
      <mass value="0.11904336"/>
      <inertia ixx="0.097950272" ixy="0.0012119368" ixz="-0.00021223016" iyx="0.00122119368" iyy="0.032848287" iyz="-0.0019474021" izx="-0.00021223016" izy="-0.0019474021" izz="0.11493509"/>
    </inertial>
    <collision>
      <origin xyz="0.000079 0.018242 0.013873"/>
      <geometry>
        <box size="0.001 0.001 0.001"/>
      </geometry>
    </collision>
    <visual>
      <origin rpy="0 0 0" xyz="0 0 0"/>
      <geometry>
        <mesh filename="package://darwin_description/meshes/thigh1_l.STL" scale="1 1 1"/>
      </geometry>
      <material name="grey"/>
    </visual>
  </link>
  <link name="MP_THIGH2_L">
    <inertial>
      <origin xyz="-0.062965 -0.000323 0.000692"/>
      <mass value="0.11904336"/>
      <inertia ixx="0.097950272" ixy="0.0012119368" ixz="-0.00021223016" iyx="0.00122119368" iyy="0.032848287" iyz="-0.0019474021" izx="-0.00021223016" izy="-0.0019474021" izz="0.11493509"/>
    </inertial>
    <collision>
      <origin xyz="-0.062965 -0.000323 0.000692"/>
      <geometry>
        <box size="0.093 0.035 0.045"/>
      </geometry>
    </collision>
    <visual>
      <origin rpy="0 0 0" xyz="0 0 0"/>
      <geometry>
        <mesh filename="package://darwin_description/meshes/thigh2_l.STL" scale="1 1 1"/>
      </geometry>
      <material name="grey"/>
    </visual>
  </link>
  <link name="MP_TIBIA_L">
    <inertial>
      <origin xyz="-0.053955 0.006548 -0.000592"/>
      <mass value="0.070309794"/>
      <inertia ixx="0.093369608" ixy="-0.00093567395" ixz="-0.00023992085" iyx="-0.00093567395" iyy="0.046295534" iyz="-0.012858493" izx="-0.00023992085" izy="-0.012858493" izz="0.11351516"/>
    </inertial>
    <collision>
      <origin xyz="-0.053955 0.006548 -0.000592"/>
      <geometry>
        <box size="0.093 0.035 0.045"/>
      </geometry>
    </collision>
    <visual>
      <origin rpy="0 0 0" xyz="0 0 0"/>
      <geometry>
        <mesh filename="package://darwin_description/meshes/tibia_l.STL" scale="1 1 1"/>
      </geometry>
      <material name="grey"/>
    </visual>
  </link>
  <link name="MP_ANKLE1_L">
    <inertial>
      <origin xyz="-0.000214 -0.018536 0.013873"/>
      <mass value="0.16710792"/>
      <inertia ixx="0.12079175" ixy="-0.00079781067" ixz="-0.00039322246" iyx="-0.00079781067" iyy="0.10885465" iyz="0.0070770117" izx="-0.00039322246" izy="0.0070770117" izz="0.041871103"/>
    </inertial>
    <collision>
      <origin xyz="-0.000214 -0.018536 0.013873"/>
      <geometry>
        <box size="0.028652 0.08175 0.045"/>
      </geometry>
    </collision>
    <visual>
      <origin rpy="0 0 0" xyz="0 0 0"/>
      <geometry>
        <mesh filename="package://darwin_description/meshes/ankle1_l.STL" scale="1 1 1"/>
      </geometry>
      <material name="grey"/>
    </visual>
  </link>
  <link name="MP_ANKLE2_L">
    <inertial>
      <origin xyz="-0.025995 -0.009506 -0.000503"/>
      <mass value="0.0794462"/>
      <inertia ixx="0.12079175" ixy="-0.00079781067" ixz="-0.00039322246" iyx="-0.00079781067" iyy="0.10885465" iyz="0.0070770117" izx="-0.00039322246" izy="0.0070770117" izz="0.041871103"/>
    </inertial>
    <collision>
      <origin xyz="-0.025995 -0.009506 -0.000503"/>
      <geometry>
        <box size="0.008 0.066 0.104"/>
      </geometry>
    </collision>
    <visual>
      <origin rpy="0 0 0" xyz="0 0 0"/>
      <geometry>
        <mesh filename="package://darwin_description/meshes/ankle2_l.STL" scale="1 1 1"/>
      </geometry>
      <material name="grey"/>
    </visual>
  </link>
  <link name="MP_PELVIS_R">
    <inertial>
      <origin xyz="0.000000 0.000480 0.018437"/>
      <mass value="0.197"/>
      <inertia ixx="0.12259691" ixy="0.00071127469" ixz="0.00081143913" iyx="0.00071127469" iyy="0.11066637" iyz="-0.0071635476" izx="0.00081143913" izy="-0.0071635476" izz="0.041877668"/>
    </inertial>
    <collision>
      <origin xyz="0.000000 0.010580 0.028437"/>
      <geometry>
        <box size="0.045 0.08175 0.028652"/>
      </geometry>
    </collision>
    <visual>
      <origin rpy="0 0 0" xyz="0 0 0"/>
      <geometry>
        <mesh filename="package://darwin_description/meshes/pelvis_r.STL" scale="1 1 1"/>
      </geometry>
      <material name="grey"/>
    </visual>
  </link>
  <link name="MP_THIGH1_R">
    <inertial>
      <origin xyz="0.000079 -0.018242 0.0138735"/>
      <mass value="0.11904336"/>
      <inertia ixx="0.097950272" ixy="0.0012119368" ixz="-0.00021223016" iyx="0.00122119368" iyy="0.032848287" iyz="-0.0019474021" izx="-0.00021223016" izy="-0.0019474021" izz="0.11493509"/>
    </inertial>
    <collision>
      <origin xyz="0.000079 -0.018242 0.0138735"/>
      <geometry>
        <box size="0.001 0.001 0.001"/>
      </geometry>
    </collision>
    <visual>
      <origin rpy="0 0 0" xyz="0 0 0"/>
      <geometry>
        <mesh filename="package://darwin_description/meshes/thigh1_r.STL" scale="1 1 1"/>
      </geometry>
      <material name="grey"/>
    </visual>
  </link>
  <link name="MP_THIGH2_R">
    <inertial>
      <origin xyz="0.062965 -0.000323 0.000692"/>
      <mass value="0.11904336"/>
      <inertia ixx="0.097950272" ixy="0.0012119368" ixz="-0.00021223016" iyx="0.00122119368" iyy="0.032848287" iyz="-0.0019474021" izx="-0.00021223016" izy="-0.0019474021" izz="0.11493509"/>
    </inertial>
    <collision>
      <origin xyz="0.062965 -0.000323 0.000692"/>
      <geometry>
        <box size="0.093 0.035 0.045"/>
      </geometry>
    </collision>
    <visual>
      <origin rpy="0 0 0" xyz="0 0 0"/>
      <geometry>
        <mesh filename="package://darwin_description/meshes/thigh2_r.STL" scale="1 1 1"/>
      </geometry>
      <material name="grey"/>
    </visual>
  </link>
  <link name="MP_TIBIA_R">
    <inertial>
      <origin xyz="0.053955 0.006548 -0.000592"/>
      <mass value="0.070309794"/>
      <inertia ixx="0.093369608" ixy="-0.00093567395" ixz="-0.00023992085" iyx="-0.00093567395" iyy="0.046295534" iyz="-0.012858493" izx="-0.00023992085" izy="-0.012858493" izz="0.11351516"/>
    </inertial>
    <collision>
      <origin xyz="0.053955 0.006548 -0.000592"/>
      <geometry>
        <box size="0.093 0.035 0.045"/>
      </geometry>
    </collision>
    <visual>
      <origin rpy="0 0 0" xyz="0 0 0"/>
      <geometry>
        <mesh filename="package://darwin_description/meshes/tibia_r.STL" scale="1 1 1"/>
      </geometry>
      <material name="grey"/>
    </visual>
  </link>
  <link name="MP_ANKLE1_R">
    <inertial>
      <origin xyz="-0.000214 -0.018536 -0.013873"/>
      <mass value="0.16710792"/>
      <inertia ixx="0.12079175" ixy="-0.00079781067" ixz="-0.00039322246" iyx="-0.00079781067" iyy="0.10885465" iyz="0.0070770117" izx="-0.00039322246" izy="0.0070770117" izz="0.041871103"/>
    </inertial>
    <collision>
      <origin xyz="-0.000214 -0.018536 0.013873"/>
      <geometry>
        <box size="0.028652 0.08175 0.045"/>
      </geometry>
    </collision>
    <visual>
      <origin rpy="0 0 0" xyz="0 0 0"/>
      <geometry>
        <mesh filename="package://darwin_description/meshes/ankle1_r.STL" scale="1 1 1"/>
      </geometry>
      <material name="grey"/>
    </visual>
  </link>
  <link name="MP_ANKLE2_R">
    <inertial>
      <origin xyz="0.025995 -0.009506 -0.000503"/>
      <mass value="0.0794462"/>
      <inertia ixx="0.12079175" ixy="-0.00079781067" ixz="-0.00039322246" iyx="-0.00079781067" iyy="0.10885465" iyz="0.0070770117" izx="-0.00039322246" izy="0.0070770117" izz="0.041871103"/>
    </inertial>
    <collision>
      <origin xyz="0.025995 -0.009506 -0.000503"/>
      <geometry>
        <box size="0.008 0.066 0.104"/>
      </geometry>
    </collision>
    <visual>
      <origin rpy="0 0 0" xyz="0 0 0"/>
      <geometry>
        <mesh filename="package://darwin_description/meshes/ankle2_r.STL" scale="1 1 1"/>
      </geometry>
      <material name="grey"/>
    </visual>
  </link>
  <link name="l_sole">
    <inertial>
    <origin xyz="0 0 0" rpy="0 0 0" />
    <mass value="1e-9" />
    <inertia ixx="0" ixy="0" ixz="0" iyy="0" iyz="0" izz="0" />
    </inertial>
  </link>
  <link name="r_sole">
   <inertial>
    <origin xyz="0 0 0" rpy="0 0 0" />
    <mass value="1e-9" />
    <inertia ixx="0" ixy="0" ixz="0" iyy="0" iyz="0" izz="0" />
    </inertial>
  </link>

  <joint name="r_sole_joint" type="fixed">
    <parent link="MP_ANKLE2_R"/>
    <child link="r_sole"/>
    <origin rpy="0 -1.57 0" xyz="0.033 -0.01 0"/>
  </joint>
  <joint name="l_sole_joint" type="fixed">
    <parent link="MP_ANKLE2_L"/>
    <child link="l_sole"/>
    <origin rpy="3.14 -1.57 0" xyz="-0.033 -0.01 0"/>
  </joint>
  <joint name="LHipYaw" type="revolute">
    <parent link="MP_BODY"/>
    <child link="MP_PELVIS_L"/>
    <origin rpy="0 3.14159 -1.5707963" xyz="-0.005 0.037 -0.09355"/>
    <axis xyz="0 0 1"/>
    <limit effort="2.8" lower="-0.69" upper="2.5" velocity="5.6548668"/>
  </joint>
  <joint name="LHipRoll" type="revolute">
    <parent link="MP_PELVIS_L"/>
    <child link="MP_THIGH1_L"/>
    <origin rpy="1.5707963 0 0" xyz="0 0 0.028652"/>
    <axis xyz="0 0 1"/>
    <limit effort="2.8" lower="-1" upper="0.93" velocity="5.6548668"/>
  </joint>
  <joint name="LHipPitch" type="revolute">
    <parent link="MP_THIGH1_L"/>
    <child link="MP_THIGH2_L"/>
    <origin rpy="1.5707963 0 -1.5707963" xyz="0 0 0"/>
    <axis xyz="0 0 1"/>
    <limit effort="2.8" lower="-0.5" upper="1.68" velocity="5.6548668"/>
  </joint>
  <joint name="LKnee" type="revolute">
    <parent link="MP_THIGH2_L"/>
    <child link="MP_TIBIA_L"/>
    <origin rpy="0 0 0" xyz="-0.093 0 0"/>
    <axis xyz="0 0 1"/>
    <limit effort="2.8" lower="-2.25" upper="0.0" velocity="5.6548668"/>
  </joint>
  <joint name="LAnklePitch" type="revolute">
    <parent link="MP_TIBIA_L"/>
    <child link="MP_ANKLE1_L"/>
    <origin rpy="3.14159 0 0" xyz="-0.093 0 0"/>
    <axis xyz="0 0 1"/>
    <limit effort="2.8" lower="-1.39" upper="1.22" velocity="5.6548668"/>
  </joint>
  <joint name="LAnkleRoll" type="revolute">
    <parent link="MP_ANKLE1_L"/>
    <child link="MP_ANKLE2_L"/>
    <origin rpy="-1.5707963 0 0" xyz="0 0 0"/>
    <axis xyz="0 0 1"/>
    <limit effort="2.8" lower="-1.02" upper="0.6" velocity="5.6548668"/>
  </joint>
  <joint name="RHipYaw" type="revolute">
    <parent link="MP_BODY"/>
    <child link="MP_PELVIS_R"/>
    <origin rpy="0 3.14159 1.5707963" xyz="-0.005 -0.037 -0.09355"/>
    <axis xyz="0 0 1"/>
    <limit effort="2.8" lower="-2.42" upper="0.66" velocity="5.6548668"/>
  </joint>
  <joint name="RHipRoll" type="revolute">
    <parent link="MP_PELVIS_R"/>
    <child link="MP_THIGH1_R"/>
    <origin rpy="-1.5707963 0 0" xyz="0 0 0.028652"/>
    <axis xyz="0 0 1"/>
    <limit effort="2.8" lower="-1.01" upper="1.01" velocity="5.6548668"/>
  </joint>
  <joint name="RHipPitch" type="revolute">
    <parent link="MP_THIGH1_R"/>
    <child link="MP_THIGH2_R"/>
    <origin rpy="1.5707963 0 -1.5707963" xyz="0 0 0"/>
    <axis xyz="0 0 1"/>
    <limit effort="2.8" lower="-1.77" upper="0.45" velocity="5.6548668"/>
  </joint>
  <joint name="RKnee" type="revolute">
    <parent link="MP_THIGH2_R"/>
    <child link="MP_TIBIA_R"/>
    <origin rpy="0 0 0" xyz="0.093 0 0"/>
    <axis xyz="0 0 1"/>
    <limit effort="2.8" lower="0" upper="2.25" velocity="5.6548668"/>
  </joint>
  <joint name="RAnklePitch" type="revolute">
    <parent link="MP_TIBIA_R"/>
    <child link="MP_ANKLE1_R"/>
    <origin rpy="3.14159 0 0" xyz="0.093 0 0"/>
    <axis xyz="0 0 1"/>
    <limit effort="2.8" lower="-1.24" upper="1.38" velocity="5.6548668"/>
  </joint>
  <joint name="RAnkleRoll" type="revolute">
    <parent link="MP_ANKLE1_R"/>
    <child link="MP_ANKLE2_R"/>
    <origin rpy="-1.5707963 0 0" xyz="0 0 0"/>
    <axis xyz="0 0 1"/>
    <limit effort="2.8" lower="-0.68" upper="1.04" velocity="5.6548668"/>
  </joint>
  <transmission name="LHipYaw_transmssion">
    <type>transmission_interface/SimpleTransmission</type>
    <joint name="LHipYaw">
      <hardwareInterface>EffortJointInterface</hardwareInterface>
    </joint>
    <actuator name="LHipYaw_motor">
      <hardwareInterface>EffortJointInterface</hardwareInterface>
      <mechanicalReduction>1</mechanicalReduction>
    </actuator>
  </transmission>
  <gazebo reference="LHipYaw">
    <implicitSpringDamper>1</implicitSpringDamper>
  </gazebo>
  <transmission name="LHipRoll_transmssion">
    <type>transmission_interface/SimpleTransmission</type>
    <joint name="LHipRoll">
      <hardwareInterface>EffortJointInterface</hardwareInterface>
    </joint>
    <actuator name="LHipRoll_motor">
      <hardwareInterface>EffortJointInterface</hardwareInterface>
      <mechanicalReduction>1</mechanicalReduction>
    </actuator>
  </transmission>
  <gazebo reference="LHipRoll">
    <implicitSpringDamper>1</implicitSpringDamper>
  </gazebo>
  <transmission name="LHipPitch_transmssion">
    <type>transmission_interface/SimpleTransmission</type>
    <joint name="LHipPitch">
      <hardwareInterface>EffortJointInterface</hardwareInterface>
    </joint>
    <actuator name="LHipPitch_motor">
      <hardwareInterface>EffortJointInterface</hardwareInterface>
      <mechanicalReduction>1</mechanicalReduction>
    </actuator>
  </transmission>
  <gazebo reference="LHipPitch">
    <implicitSpringDamper>1</implicitSpringDamper>
  </gazebo>
  <transmission name="LKnee_transmssion">
    <type>transmission_interface/SimpleTransmission</type>
    <joint name="LKnee">
      <hardwareInterface>EffortJointInterface</hardwareInterface>
    </joint>
    <actuator name="LKnee_motor">
      <hardwareInterface>EffortJointInterface</hardwareInterface>
      <mechanicalReduction>1</mechanicalReduction>
    </actuator>
  </transmission>
  <gazebo reference="LKnee">
    <implicitSpringDamper>1</implicitSpringDamper>
  </gazebo>
  <transmission name="LAnklePitch_transmssion">
    <type>transmission_interface/SimpleTransmission</type>
    <joint name="LAnklePitch">
      <hardwareInterface>EffortJointInterface</hardwareInterface>
    </joint>
    <actuator name="LAnklePitch_motor">
      <hardwareInterface>EffortJointInterface</hardwareInterface>
      <mechanicalReduction>1</mechanicalReduction>
    </actuator>
  </transmission>
  <gazebo reference="LAnklePitch">
    <implicitSpringDamper>1</implicitSpringDamper>
  </gazebo>
  <transmission name="LAnkleRoll_transmssion">
    <type>transmission_interface/SimpleTransmission</type>
    <joint name="LAnkleRoll">
      <hardwareInterface>EffortJointInterface</hardwareInterface>
    </joint>
    <actuator name="LAnkleRoll_motor">
      <hardwareInterface>EffortJointInterface</hardwareInterface>
      <mechanicalReduction>1</mechanicalReduction>
    </actuator>
  </transmission>
  <gazebo reference="LAnkleRoll">
    <implicitSpringDamper>1</implicitSpringDamper>
  </gazebo>
  <transmission name="RHipYaw_transmssion">
    <type>transmission_interface/SimpleTransmission</type>
    <joint name="RHipYaw">
      <hardwareInterface>EffortJointInterface</hardwareInterface>
    </joint>
    <actuator name="RHipYaw_motor">
      <hardwareInterface>EffortJointInterface</hardwareInterface>
      <mechanicalReduction>1</mechanicalReduction>
    </actuator>
  </transmission>
  <gazebo reference="RHipYaw">
    <implicitSpringDamper>1</implicitSpringDamper>
  </gazebo>
  <transmission name="RHipRoll_transmssion">
    <type>transmission_interface/SimpleTransmission</type>
    <joint name="RHipRoll">
      <hardwareInterface>EffortJointInterface</hardwareInterface>
    </joint>
    <actuator name="RHipRoll_motor">
      <hardwareInterface>EffortJointInterface</hardwareInterface>
      <mechanicalReduction>1</mechanicalReduction>
    </actuator>
  </transmission>
  <gazebo reference="RHipRoll">
    <implicitSpringDamper>1</implicitSpringDamper>
  </gazebo>
  <transmission name="RHipPitch_transmssion">
    <type>transmission_interface/SimpleTransmission</type>
    <joint name="RHipPitch">
      <hardwareInterface>EffortJointInterface</hardwareInterface>
    </joint>
    <actuator name="RHipPitch_motor">
      <hardwareInterface>EffortJointInterface</hardwareInterface>
      <mechanicalReduction>1</mechanicalReduction>
    </actuator>
  </transmission>
  <gazebo reference="RHipPitch">
    <implicitSpringDamper>1</implicitSpringDamper>
  </gazebo>
  <transmission name="RKnee_transmssion">
    <type>transmission_interface/SimpleTransmission</type>
    <joint name="RKnee">
      <hardwareInterface>EffortJointInterface</hardwareInterface>
    </joint>
    <actuator name="RKnee_motor">
      <hardwareInterface>EffortJointInterface</hardwareInterface>
      <mechanicalReduction>1</mechanicalReduction>
    </actuator>
  </transmission>
  <gazebo reference="RKnee">
    <implicitSpringDamper>1</implicitSpringDamper>
  </gazebo>
  <transmission name="RAnklePitch_transmssion">
    <type>transmission_interface/SimpleTransmission</type>
    <joint name="RAnklePitch">
      <hardwareInterface>EffortJointInterface</hardwareInterface>
    </joint>
    <actuator name="RAnklePitch_motor">
      <hardwareInterface>EffortJointInterface</hardwareInterface>
      <mechanicalReduction>1</mechanicalReduction>
    </actuator>
  </transmission>
  <gazebo reference="RAnklePitch">
    <implicitSpringDamper>1</implicitSpringDamper>
  </gazebo>
  <transmission name="RAnkleRoll_transmssion">
    <type>transmission_interface/SimpleTransmission</type>
    <joint name="RAnkleRoll">
      <hardwareInterface>EffortJointInterface</hardwareInterface>
    </joint>
    <actuator name="RAnkleRoll_motor">
      <hardwareInterface>EffortJointInterface</hardwareInterface>
      <mechanicalReduction>1</mechanicalReduction>
    </actuator>
  </transmission>
  <gazebo reference="RAnkleRoll">
    <implicitSpringDamper>1</implicitSpringDamper>
  </gazebo>
  <gazebo reference="MP_ANKLE2_L">
    <material>Gazebo/White</material>
    <mu1>9000</mu1>
    <mu2>9000</mu2>
    <kp>1000000.0</kp>
    <kd>10.0</kd>
    <minDepth>0.000001</minDepth>
    <maxContacts>100</maxContacts>
  </gazebo>
  <gazebo reference="MP_ANKLE2_R">
    <material>Gazebo/White</material>
    <mu1>9000</mu1>
    <mu2>9000</mu2>
    <kp>1000000.0</kp>
    <kd>10.0</kd>
    <minDepth>0.000001</minDepth>
    <maxContacts>100</maxContacts>
  </gazebo>
  <gazebo>
    <plugin filename="libgazebo_ros_control.so" name="gazebo_ros_control">
      <robotNamespace>darwin</robotNamespace>
    </plugin>
  </gazebo>
</robot>
